<?xml version="1.0" ?>
<mujoco model="mujocoRobotDescription">
  <compiler angle="radian" meshdir="assets"/>
  
  <option iterations="100" solver="Newton" gravity="0 0 -9.81">
    <flag contact="enable" override="enable"/>
  </option>
  
  <default>
    <default class="mujocoRobotDescription">
      <joint frictionloss="0.1" armature="0.005"/>
      <position kp="50" dampratio="1"/>
      <default class="visual">
        <geom type="mesh" contype="0" conaffinity="0" group="2"/>
      </default>
      <default class="collision">
        <geom group="3" 
              friction="0.8 0.005 0.0001"
              solref="0.01 1" 
              solimp="0.9 0.95 0.001"/>
      </default>
    </default>
  </default>
  
  <worldbody>
    <body name="part_1" pos="0 0 0" quat="1 0 0 0" childclass="mujocoRobotDescription">
      <freejoint name="part_1_freejoint"/>
      <inertial pos="0.13887 7.28939e-18 0.297" mass="51.4035" fullinertia="4.37997 16.1482 12.3346 1.20405e-10 -3.35204 6.95154e-11"/>
      
      <!-- Simple collision box for reliable collision detection -->
      <geom name="part_1_collision_box" type="box" size="0.3 0.15 0.3" 
            pos="0 0 0.3" rgba="0 1 0 0.3"
            contype="1" conaffinity="1"
            friction="0.8 0.005 0.0001"
            solref="0.01 1" 
            solimp="0.9 0.95 0.001"/>
      
      <geom type="mesh" class="visual" pos="-0.543884 0.11 0.235048" quat="0.612372 -0.612372 0.353553 0.353553" mesh="part_1" material="part_1_material"/>
      
      <geom type="mesh" class="visual" pos="-0.427032 0 0.232654" quat="0.965926 8.34565e-18 -0.258819 1.20457e-16" mesh="part_1__2" material="part_1__2_material"/>
      
      <geom type="mesh" class="visual" pos="0 0 0" quat="1 0 0 0" mesh="part_1__3" material="part_1__3_material"/>
      
      <geom type="mesh" class="visual" pos="-0.340429 -0.09 0.282654" quat="0.683013 0.183013 -0.183013 -0.683013" mesh="part_1__4" material="part_1__4_material"/>
      
      <geom type="mesh" class="visual" pos="-0.526625 0 0.175154" quat="0.683013 -0.183013 -0.183013 0.683013" mesh="part_1__5" material="part_1__5_material"/>
      
      <geom type="mesh" class="visual" pos="-0.370679 -0.11 0.335048" quat="0.353553 -0.353553 -0.612372 -0.612372" mesh="part_1" material="part_1_material"/>
      
      <geom type="mesh" class="visual" pos="-0.513634 0.09 0.182654" quat="0.683013 -0.183013 -0.183013 0.683013" mesh="part_1__4" material="part_1__4_material"/>
      
      <body name="part_1_2" pos="0.300014 -1.88633e-17 0.722274" quat="1 0 0 0">
        <joint name="slider_joint" type="slide" axis="0.866025 0 0.5" damping="0.5" frictionloss="0.02"/>
        
        <inertial pos="0 0 0" mass="1.881" fullinertia="0.0088759 0.00340693 0.0101542 9.10487e-19 -0.00110708 9.51864e-19"/>
        
        <!-- Simple collision box for slider -->
        <geom name="part_1_2_collision_box" type="box" size="0.15 0.1 0.15"
              pos="0 0 0" rgba="1 0 0 0.3"
              contype="1" conaffinity="1"
              friction="0.8 0.005 0.0001"
              solref="0.01 1" 
              solimp="0.9 0.95 0.001"/>
        
        <geom type="mesh" class="visual" pos="0.005194 0 0.002998" quat="0.258819 -9.4075e-17 0.965926 1.14041e-16" mesh="part_1__6" material="part_1__6_material"/>
      </body>
    </body>
  </worldbody>
  
  <asset>
    <mesh file="part_1__3.stl"/>
    <mesh file="part_1__2.stl"/>
    <mesh file="part_1.stl"/>
    <mesh file="part_1__4.stl"/>
    <mesh file="part_1__6.stl"/>
    <mesh file="part_1__5.stl"/>
    <material name="part_1_material" rgba="0.596078 0.176471 0.0509804 1"/>
    <material name="part_1__2_material" rgba="0.917647 0.917647 0.917647 1"/>
    <material name="part_1__3_material" rgba="0.4 0.4 0.4 1"/>
    <material name="part_1__4_material" rgba="0.647059 0.647059 0.647059 1"/>
    <material name="part_1__5_material" rgba="0.4 0.4 0.4 1"/>
    <material name="part_1__6_material" rgba="0.647059 0.647059 0.647059 1"/>
  </asset>
  
  <actuator>
    <motor name="slider_force" joint="slider_joint" 
           gear="1" 
           ctrllimited="true" 
           ctrlrange="-50 50"/>
  </actuator>
  
  <equality/>
</mujoco>